{
 "cells": [
  {
   "cell_type": "code",
   "execution_count": 26,
   "id": "cb38717f",
   "metadata": {},
   "outputs": [],
   "source": [
    "import numpy as np\n",
    "import pandas as pd\n",
    "import seaborn as sns\n",
    "import os\n",
    "import matplotlib.pyplot as plt\n",
    "import time\n",
    "from sklearn.preprocessing import StandardScaler\n",
    "from sklearn.model_selection import train_test_split\n",
    "\n",
    "import keras\n",
    "from keras.models import Sequential\n",
    "from keras.layers import Dense\n",
    "\n",
    "# fix random seed for reproducibility\n",
    "seed = 155\n",
    "np.random.seed(seed)\n",
    "\n",
    "# load dataset\n",
    "\n",
    "# download directly from website\n",
    "\n",
    "# import from local directory\n",
    "dataset = pd.read_csv(\"finalma3.csv\", header=None).values\n"
   ]
  },
  {
   "cell_type": "code",
   "execution_count": 19,
   "id": "a64f7a81",
   "metadata": {},
   "outputs": [
    {
     "data": {
      "text/plain": [
       "array([[1.000e+00, 2.009e+03, 1.000e+00, 8.988e+01, 1.400e+01],\n",
       "       [2.000e+00, 2.009e+03, 1.000e+00, 8.650e+01, 1.400e+01],\n",
       "       [3.000e+00, 2.009e+03, 1.000e+00, 8.638e+01, 1.400e+01],\n",
       "       ...,\n",
       "       [      inf, 1.996e+03, 2.100e+01, 1.018e+02, 1.000e+00],\n",
       "       [      inf, 1.996e+03, 2.100e+01, 1.002e+02, 1.000e+00],\n",
       "       [      inf, 1.996e+03, 2.100e+01, 1.016e+02, 1.000e+00]],\n",
       "      dtype=float16)"
      ]
     },
     "execution_count": 19,
     "metadata": {},
     "output_type": "execute_result"
    }
   ],
   "source": []
  },
  {
   "cell_type": "code",
   "execution_count": 27,
   "id": "753eb659",
   "metadata": {},
   "outputs": [],
   "source": [
    "X_train, X_test, Y_train, Y_test = train_test_split(dataset[:,4], dataset[:,4], \n",
    "                                                    test_size=0.25, random_state=87)"
   ]
  },
  {
   "cell_type": "code",
   "execution_count": 28,
   "id": "4120967b",
   "metadata": {},
   "outputs": [],
   "source": [
    "np.random.seed(seed)\n",
    "my_first_nn = Sequential() # create model\n",
    "my_first_nn.add(Dense(5, input_dim=4, activation='relu')) # hidden layer\n",
    "my_first_nn.add(Dense(1, activation='sigmoid')) # output layer\n",
    "my_first_nn.compile(loss='binary_crossentropy', optimizer='adam', metrics=['accuracy'])"
   ]
  },
  {
   "cell_type": "code",
   "execution_count": 29,
   "id": "b70e2db0",
   "metadata": {},
   "outputs": [],
   "source": [
    "# optional\n",
    "from keras.callbacks import ModelCheckpoint\n",
    "# specify filepath- this will write a new file for each epoch with the epoch number contained within the filename\n",
    "filepath=\"nn_weights-{epoch:02d}.hdf5\"\n",
    "checkpoint = keras.callbacks.ModelCheckpoint(filepath, monitor='val_acc', verbose=0, \n",
    "                                             save_weights_only=False, save_best_only=False, mode='max')\n"
   ]
  },
  {
   "cell_type": "code",
   "execution_count": 30,
   "id": "cbf1c745",
   "metadata": {},
   "outputs": [
    {
     "name": "stdout",
     "output_type": "stream",
     "text": [
      "WARNING:tensorflow:Model was constructed with shape (None, 4) for input KerasTensor(type_spec=TensorSpec(shape=(None, 4), dtype=tf.float32, name='dense_6_input'), name='dense_6_input', description=\"created by layer 'dense_6_input'\"), but it was called on an input with incompatible shape (111428,).\n"
     ]
    },
    {
     "ename": "ValueError",
     "evalue": "in user code:\n\n    File \"C:\\Users\\Himadhith\\AppData\\Local\\Programs\\Python\\Python39\\lib\\site-packages\\keras\\engine\\training.py\", line 878, in train_function  *\n        return step_function(self, iterator)\n    File \"C:\\Users\\Himadhith\\AppData\\Local\\Programs\\Python\\Python39\\lib\\site-packages\\keras\\engine\\training.py\", line 867, in step_function  **\n        outputs = model.distribute_strategy.run(run_step, args=(data,))\n    File \"C:\\Users\\Himadhith\\AppData\\Local\\Programs\\Python\\Python39\\lib\\site-packages\\keras\\engine\\training.py\", line 860, in run_step  **\n        outputs = model.train_step(data)\n    File \"C:\\Users\\Himadhith\\AppData\\Local\\Programs\\Python\\Python39\\lib\\site-packages\\keras\\engine\\training.py\", line 808, in train_step\n        y_pred = self(x, training=True)\n    File \"C:\\Users\\Himadhith\\AppData\\Local\\Programs\\Python\\Python39\\lib\\site-packages\\keras\\utils\\traceback_utils.py\", line 67, in error_handler\n        raise e.with_traceback(filtered_tb) from None\n    File \"C:\\Users\\Himadhith\\AppData\\Local\\Programs\\Python\\Python39\\lib\\site-packages\\keras\\engine\\input_spec.py\", line 227, in assert_input_compatibility\n        raise ValueError(f'Input {input_index} of layer \"{layer_name}\" '\n\n    ValueError: Exception encountered when calling layer \"sequential_3\" (type Sequential).\n    \n    Input 0 of layer \"dense_6\" is incompatible with the layer: expected min_ndim=2, found ndim=1. Full shape received: (111428,)\n    \n    Call arguments received:\n      • inputs=tf.Tensor(shape=(111428,), dtype=float32)\n      • training=True\n      • mask=None\n",
     "output_type": "error",
     "traceback": [
      "\u001b[1;31m---------------------------------------------------------------------------\u001b[0m",
      "\u001b[1;31mValueError\u001b[0m                                Traceback (most recent call last)",
      "\u001b[1;32mC:\\Users\\HIMADH~1\\AppData\\Local\\Temp/ipykernel_25360/658707955.py\u001b[0m in \u001b[0;36m<module>\u001b[1;34m\u001b[0m\n\u001b[0;32m      2\u001b[0m \u001b[1;31m# note that the fit method expects a list of callbacks\u001b[0m\u001b[1;33m\u001b[0m\u001b[1;33m\u001b[0m\u001b[0m\n\u001b[0;32m      3\u001b[0m \u001b[1;33m\u001b[0m\u001b[0m\n\u001b[1;32m----> 4\u001b[1;33m my_first_nn_fitted = my_first_nn.fit(X_train, Y_train, epochs=1, verbose=0, batch_size=X_train.shape[0],\n\u001b[0m\u001b[0;32m      5\u001b[0m                                      callbacks=[checkpoint], initial_epoch=0)\n",
      "\u001b[1;32m~\\AppData\\Local\\Programs\\Python\\Python39\\lib\\site-packages\\keras\\utils\\traceback_utils.py\u001b[0m in \u001b[0;36merror_handler\u001b[1;34m(*args, **kwargs)\u001b[0m\n\u001b[0;32m     65\u001b[0m     \u001b[1;32mexcept\u001b[0m \u001b[0mException\u001b[0m \u001b[1;32mas\u001b[0m \u001b[0me\u001b[0m\u001b[1;33m:\u001b[0m  \u001b[1;31m# pylint: disable=broad-except\u001b[0m\u001b[1;33m\u001b[0m\u001b[1;33m\u001b[0m\u001b[0m\n\u001b[0;32m     66\u001b[0m       \u001b[0mfiltered_tb\u001b[0m \u001b[1;33m=\u001b[0m \u001b[0m_process_traceback_frames\u001b[0m\u001b[1;33m(\u001b[0m\u001b[0me\u001b[0m\u001b[1;33m.\u001b[0m\u001b[0m__traceback__\u001b[0m\u001b[1;33m)\u001b[0m\u001b[1;33m\u001b[0m\u001b[1;33m\u001b[0m\u001b[0m\n\u001b[1;32m---> 67\u001b[1;33m       \u001b[1;32mraise\u001b[0m \u001b[0me\u001b[0m\u001b[1;33m.\u001b[0m\u001b[0mwith_traceback\u001b[0m\u001b[1;33m(\u001b[0m\u001b[0mfiltered_tb\u001b[0m\u001b[1;33m)\u001b[0m \u001b[1;32mfrom\u001b[0m \u001b[1;32mNone\u001b[0m\u001b[1;33m\u001b[0m\u001b[1;33m\u001b[0m\u001b[0m\n\u001b[0m\u001b[0;32m     68\u001b[0m     \u001b[1;32mfinally\u001b[0m\u001b[1;33m:\u001b[0m\u001b[1;33m\u001b[0m\u001b[1;33m\u001b[0m\u001b[0m\n\u001b[0;32m     69\u001b[0m       \u001b[1;32mdel\u001b[0m \u001b[0mfiltered_tb\u001b[0m\u001b[1;33m\u001b[0m\u001b[1;33m\u001b[0m\u001b[0m\n",
      "\u001b[1;32m~\\AppData\\Local\\Programs\\Python\\Python39\\lib\\site-packages\\tensorflow\\python\\framework\\func_graph.py\u001b[0m in \u001b[0;36mautograph_handler\u001b[1;34m(*args, **kwargs)\u001b[0m\n\u001b[0;32m   1127\u001b[0m           \u001b[1;32mexcept\u001b[0m \u001b[0mException\u001b[0m \u001b[1;32mas\u001b[0m \u001b[0me\u001b[0m\u001b[1;33m:\u001b[0m  \u001b[1;31m# pylint:disable=broad-except\u001b[0m\u001b[1;33m\u001b[0m\u001b[1;33m\u001b[0m\u001b[0m\n\u001b[0;32m   1128\u001b[0m             \u001b[1;32mif\u001b[0m \u001b[0mhasattr\u001b[0m\u001b[1;33m(\u001b[0m\u001b[0me\u001b[0m\u001b[1;33m,\u001b[0m \u001b[1;34m\"ag_error_metadata\"\u001b[0m\u001b[1;33m)\u001b[0m\u001b[1;33m:\u001b[0m\u001b[1;33m\u001b[0m\u001b[1;33m\u001b[0m\u001b[0m\n\u001b[1;32m-> 1129\u001b[1;33m               \u001b[1;32mraise\u001b[0m \u001b[0me\u001b[0m\u001b[1;33m.\u001b[0m\u001b[0mag_error_metadata\u001b[0m\u001b[1;33m.\u001b[0m\u001b[0mto_exception\u001b[0m\u001b[1;33m(\u001b[0m\u001b[0me\u001b[0m\u001b[1;33m)\u001b[0m\u001b[1;33m\u001b[0m\u001b[1;33m\u001b[0m\u001b[0m\n\u001b[0m\u001b[0;32m   1130\u001b[0m             \u001b[1;32melse\u001b[0m\u001b[1;33m:\u001b[0m\u001b[1;33m\u001b[0m\u001b[1;33m\u001b[0m\u001b[0m\n\u001b[0;32m   1131\u001b[0m               \u001b[1;32mraise\u001b[0m\u001b[1;33m\u001b[0m\u001b[1;33m\u001b[0m\u001b[0m\n",
      "\u001b[1;31mValueError\u001b[0m: in user code:\n\n    File \"C:\\Users\\Himadhith\\AppData\\Local\\Programs\\Python\\Python39\\lib\\site-packages\\keras\\engine\\training.py\", line 878, in train_function  *\n        return step_function(self, iterator)\n    File \"C:\\Users\\Himadhith\\AppData\\Local\\Programs\\Python\\Python39\\lib\\site-packages\\keras\\engine\\training.py\", line 867, in step_function  **\n        outputs = model.distribute_strategy.run(run_step, args=(data,))\n    File \"C:\\Users\\Himadhith\\AppData\\Local\\Programs\\Python\\Python39\\lib\\site-packages\\keras\\engine\\training.py\", line 860, in run_step  **\n        outputs = model.train_step(data)\n    File \"C:\\Users\\Himadhith\\AppData\\Local\\Programs\\Python\\Python39\\lib\\site-packages\\keras\\engine\\training.py\", line 808, in train_step\n        y_pred = self(x, training=True)\n    File \"C:\\Users\\Himadhith\\AppData\\Local\\Programs\\Python\\Python39\\lib\\site-packages\\keras\\utils\\traceback_utils.py\", line 67, in error_handler\n        raise e.with_traceback(filtered_tb) from None\n    File \"C:\\Users\\Himadhith\\AppData\\Local\\Programs\\Python\\Python39\\lib\\site-packages\\keras\\engine\\input_spec.py\", line 227, in assert_input_compatibility\n        raise ValueError(f'Input {input_index} of layer \"{layer_name}\" '\n\n    ValueError: Exception encountered when calling layer \"sequential_3\" (type Sequential).\n    \n    Input 0 of layer \"dense_6\" is incompatible with the layer: expected min_ndim=2, found ndim=1. Full shape received: (111428,)\n    \n    Call arguments received:\n      • inputs=tf.Tensor(shape=(111428,), dtype=float32)\n      • training=True\n      • mask=None\n"
     ]
    }
   ],
   "source": [
    "# verbose=0 suppresses the file writing message\n",
    "# note that the fit method expects a list of callbacks\n",
    "\n",
    "my_first_nn_fitted = my_first_nn.fit(X_train, Y_train,epochs=1, batch_size=X_train.shape[0],verbose=0, \n",
    "                                     callbacks=[checkpoint], initial_epoch=0)"
   ]
  },
  {
   "cell_type": "code",
   "execution_count": 17,
   "id": "745b45c3",
   "metadata": {},
   "outputs": [
    {
     "name": "stdout",
     "output_type": "stream",
     "text": [
      "WARNING:tensorflow:Model was constructed with shape (None, 4) for input KerasTensor(type_spec=TensorSpec(shape=(None, 4), dtype=tf.float32, name='dense_2_input'), name='dense_2_input', description=\"created by layer 'dense_2_input'\"), but it was called on an input with incompatible shape (None,).\n"
     ]
    },
    {
     "ename": "ValueError",
     "evalue": "in user code:\n\n    File \"C:\\Users\\Himadhith\\AppData\\Local\\Programs\\Python\\Python39\\lib\\site-packages\\keras\\engine\\training.py\", line 1366, in test_function  *\n        return step_function(self, iterator)\n    File \"C:\\Users\\Himadhith\\AppData\\Local\\Programs\\Python\\Python39\\lib\\site-packages\\keras\\engine\\training.py\", line 1356, in step_function  **\n        outputs = model.distribute_strategy.run(run_step, args=(data,))\n    File \"C:\\Users\\Himadhith\\AppData\\Local\\Programs\\Python\\Python39\\lib\\site-packages\\keras\\engine\\training.py\", line 1349, in run_step  **\n        outputs = model.test_step(data)\n    File \"C:\\Users\\Himadhith\\AppData\\Local\\Programs\\Python\\Python39\\lib\\site-packages\\keras\\engine\\training.py\", line 1303, in test_step\n        y_pred = self(x, training=False)\n    File \"C:\\Users\\Himadhith\\AppData\\Local\\Programs\\Python\\Python39\\lib\\site-packages\\keras\\utils\\traceback_utils.py\", line 67, in error_handler\n        raise e.with_traceback(filtered_tb) from None\n    File \"C:\\Users\\Himadhith\\AppData\\Local\\Programs\\Python\\Python39\\lib\\site-packages\\keras\\engine\\input_spec.py\", line 227, in assert_input_compatibility\n        raise ValueError(f'Input {input_index} of layer \"{layer_name}\" '\n\n    ValueError: Exception encountered when calling layer \"sequential_1\" (type Sequential).\n    \n    Input 0 of layer \"dense_2\" is incompatible with the layer: expected min_ndim=2, found ndim=1. Full shape received: (None,)\n    \n    Call arguments received:\n      • inputs=tf.Tensor(shape=(None,), dtype=float32)\n      • training=False\n      • mask=None\n",
     "output_type": "error",
     "traceback": [
      "\u001b[1;31m---------------------------------------------------------------------------\u001b[0m",
      "\u001b[1;31mValueError\u001b[0m                                Traceback (most recent call last)",
      "\u001b[1;32mC:\\Users\\HIMADH~1\\AppData\\Local\\Temp/ipykernel_25360/134807173.py\u001b[0m in \u001b[0;36m<module>\u001b[1;34m\u001b[0m\n\u001b[1;32m----> 1\u001b[1;33m \u001b[0mmy_first_nn\u001b[0m\u001b[1;33m.\u001b[0m\u001b[0mevaluate\u001b[0m\u001b[1;33m(\u001b[0m\u001b[0mX_test\u001b[0m\u001b[1;33m,\u001b[0m \u001b[0mY_test\u001b[0m\u001b[1;33m,\u001b[0m \u001b[0mverbose\u001b[0m\u001b[1;33m=\u001b[0m\u001b[1;36m0\u001b[0m\u001b[1;33m)\u001b[0m\u001b[1;33m\u001b[0m\u001b[1;33m\u001b[0m\u001b[0m\n\u001b[0m",
      "\u001b[1;32m~\\AppData\\Local\\Programs\\Python\\Python39\\lib\\site-packages\\keras\\utils\\traceback_utils.py\u001b[0m in \u001b[0;36merror_handler\u001b[1;34m(*args, **kwargs)\u001b[0m\n\u001b[0;32m     65\u001b[0m     \u001b[1;32mexcept\u001b[0m \u001b[0mException\u001b[0m \u001b[1;32mas\u001b[0m \u001b[0me\u001b[0m\u001b[1;33m:\u001b[0m  \u001b[1;31m# pylint: disable=broad-except\u001b[0m\u001b[1;33m\u001b[0m\u001b[1;33m\u001b[0m\u001b[0m\n\u001b[0;32m     66\u001b[0m       \u001b[0mfiltered_tb\u001b[0m \u001b[1;33m=\u001b[0m \u001b[0m_process_traceback_frames\u001b[0m\u001b[1;33m(\u001b[0m\u001b[0me\u001b[0m\u001b[1;33m.\u001b[0m\u001b[0m__traceback__\u001b[0m\u001b[1;33m)\u001b[0m\u001b[1;33m\u001b[0m\u001b[1;33m\u001b[0m\u001b[0m\n\u001b[1;32m---> 67\u001b[1;33m       \u001b[1;32mraise\u001b[0m \u001b[0me\u001b[0m\u001b[1;33m.\u001b[0m\u001b[0mwith_traceback\u001b[0m\u001b[1;33m(\u001b[0m\u001b[0mfiltered_tb\u001b[0m\u001b[1;33m)\u001b[0m \u001b[1;32mfrom\u001b[0m \u001b[1;32mNone\u001b[0m\u001b[1;33m\u001b[0m\u001b[1;33m\u001b[0m\u001b[0m\n\u001b[0m\u001b[0;32m     68\u001b[0m     \u001b[1;32mfinally\u001b[0m\u001b[1;33m:\u001b[0m\u001b[1;33m\u001b[0m\u001b[1;33m\u001b[0m\u001b[0m\n\u001b[0;32m     69\u001b[0m       \u001b[1;32mdel\u001b[0m \u001b[0mfiltered_tb\u001b[0m\u001b[1;33m\u001b[0m\u001b[1;33m\u001b[0m\u001b[0m\n",
      "\u001b[1;32m~\\AppData\\Local\\Programs\\Python\\Python39\\lib\\site-packages\\tensorflow\\python\\framework\\func_graph.py\u001b[0m in \u001b[0;36mautograph_handler\u001b[1;34m(*args, **kwargs)\u001b[0m\n\u001b[0;32m   1127\u001b[0m           \u001b[1;32mexcept\u001b[0m \u001b[0mException\u001b[0m \u001b[1;32mas\u001b[0m \u001b[0me\u001b[0m\u001b[1;33m:\u001b[0m  \u001b[1;31m# pylint:disable=broad-except\u001b[0m\u001b[1;33m\u001b[0m\u001b[1;33m\u001b[0m\u001b[0m\n\u001b[0;32m   1128\u001b[0m             \u001b[1;32mif\u001b[0m \u001b[0mhasattr\u001b[0m\u001b[1;33m(\u001b[0m\u001b[0me\u001b[0m\u001b[1;33m,\u001b[0m \u001b[1;34m\"ag_error_metadata\"\u001b[0m\u001b[1;33m)\u001b[0m\u001b[1;33m:\u001b[0m\u001b[1;33m\u001b[0m\u001b[1;33m\u001b[0m\u001b[0m\n\u001b[1;32m-> 1129\u001b[1;33m               \u001b[1;32mraise\u001b[0m \u001b[0me\u001b[0m\u001b[1;33m.\u001b[0m\u001b[0mag_error_metadata\u001b[0m\u001b[1;33m.\u001b[0m\u001b[0mto_exception\u001b[0m\u001b[1;33m(\u001b[0m\u001b[0me\u001b[0m\u001b[1;33m)\u001b[0m\u001b[1;33m\u001b[0m\u001b[1;33m\u001b[0m\u001b[0m\n\u001b[0m\u001b[0;32m   1130\u001b[0m             \u001b[1;32melse\u001b[0m\u001b[1;33m:\u001b[0m\u001b[1;33m\u001b[0m\u001b[1;33m\u001b[0m\u001b[0m\n\u001b[0;32m   1131\u001b[0m               \u001b[1;32mraise\u001b[0m\u001b[1;33m\u001b[0m\u001b[1;33m\u001b[0m\u001b[0m\n",
      "\u001b[1;31mValueError\u001b[0m: in user code:\n\n    File \"C:\\Users\\Himadhith\\AppData\\Local\\Programs\\Python\\Python39\\lib\\site-packages\\keras\\engine\\training.py\", line 1366, in test_function  *\n        return step_function(self, iterator)\n    File \"C:\\Users\\Himadhith\\AppData\\Local\\Programs\\Python\\Python39\\lib\\site-packages\\keras\\engine\\training.py\", line 1356, in step_function  **\n        outputs = model.distribute_strategy.run(run_step, args=(data,))\n    File \"C:\\Users\\Himadhith\\AppData\\Local\\Programs\\Python\\Python39\\lib\\site-packages\\keras\\engine\\training.py\", line 1349, in run_step  **\n        outputs = model.test_step(data)\n    File \"C:\\Users\\Himadhith\\AppData\\Local\\Programs\\Python\\Python39\\lib\\site-packages\\keras\\engine\\training.py\", line 1303, in test_step\n        y_pred = self(x, training=False)\n    File \"C:\\Users\\Himadhith\\AppData\\Local\\Programs\\Python\\Python39\\lib\\site-packages\\keras\\utils\\traceback_utils.py\", line 67, in error_handler\n        raise e.with_traceback(filtered_tb) from None\n    File \"C:\\Users\\Himadhith\\AppData\\Local\\Programs\\Python\\Python39\\lib\\site-packages\\keras\\engine\\input_spec.py\", line 227, in assert_input_compatibility\n        raise ValueError(f'Input {input_index} of layer \"{layer_name}\" '\n\n    ValueError: Exception encountered when calling layer \"sequential_1\" (type Sequential).\n    \n    Input 0 of layer \"dense_2\" is incompatible with the layer: expected min_ndim=2, found ndim=1. Full shape received: (None,)\n    \n    Call arguments received:\n      • inputs=tf.Tensor(shape=(None,), dtype=float32)\n      • training=False\n      • mask=None\n"
     ]
    }
   ],
   "source": [
    "my_first_nn.evaluate(X_test, Y_test, verbose=0)"
   ]
  },
  {
   "cell_type": "code",
   "execution_count": null,
   "id": "eff33b02",
   "metadata": {},
   "outputs": [],
   "source": [
    "# training loss and accuracy over the first five epochs\n",
    "[my_first_nn_fitted.history['loss'][0:5], my_first_nn_fitted.history['acc'][0:5]]"
   ]
  },
  {
   "cell_type": "code",
   "execution_count": null,
   "id": "949019e1",
   "metadata": {},
   "outputs": [],
   "source": [
    "temp_test_model = Sequential() # create model\n",
    "temp_test_model.add(Dense(5, input_dim=8, activation='relu')) # hidden layer\n",
    "temp_test_model.add(Dense(1, activation='sigmoid')) # output layer\n",
    "temp_test_model.compile(loss='binary_crossentropy', optimizer='adam', metrics=['accuracy'])\n",
    "test_over_time = []\n",
    "for i in range(len(my_first_nn_fitted.history['acc'])):\n",
    "    temp_test_model.load_weights(\"nn_weights-%02d.hdf5\" % i)\n",
    "    scores = temp_test_model.evaluate(X_test, Y_test, verbose=0)\n",
    "    # 0 is loss; 1 is accuracy\n",
    "    test_over_time.append(scores)"
   ]
  },
  {
   "cell_type": "code",
   "execution_count": null,
   "id": "9e14cc27",
   "metadata": {},
   "outputs": [],
   "source": [
    "fig, (ax1, ax2) = plt.subplots(2, 1)\n",
    "ax1.plot(range(len(my_first_nn_fitted.history['loss'])), my_first_nn_fitted.history['loss'],linestyle='-', color='blue',label='Training', lw=2)\n",
    "ax1.plot(range(len(np.array(test_over_time)[:,0])), np.array(test_over_time)[:,0], linestyle='-', color='green',label='Test', lw=2)\n",
    "ax2.plot(range(len(my_first_nn_fitted.history['acc'])), my_first_nn_fitted.history['acc'],linestyle='-', color='blue',label='Training', lw=2)\n",
    "ax2.plot(range(len(np.array(test_over_time)[:,1])), np.array(test_over_time)[:,1], linestyle='-', color='green',label='Test', lw=2)\n",
    "leg = ax1.legend(bbox_to_anchor=(0.7, 0.9), loc=2, borderaxespad=0.,fontsize=13)\n",
    "ax1.set_xticklabels('')\n",
    "#ax1.set_yscale('log')\n",
    "ax2.set_xlabel('# Epochs',fontsize=14)\n",
    "ax1.set_ylabel('Loss',fontsize=14)\n",
    "ax2.set_ylabel('Accuracy',fontsize=14)\n",
    "plt.show()"
   ]
  }
 ],
 "metadata": {
  "kernelspec": {
   "display_name": "Python 3 (ipykernel)",
   "language": "python",
   "name": "python3"
  },
  "language_info": {
   "codemirror_mode": {
    "name": "ipython",
    "version": 3
   },
   "file_extension": ".py",
   "mimetype": "text/x-python",
   "name": "python",
   "nbconvert_exporter": "python",
   "pygments_lexer": "ipython3",
   "version": "3.9.9"
  }
 },
 "nbformat": 4,
 "nbformat_minor": 5
}
